Workbook
Name Slicer_Date_Received__Month: #N/A

Sheet Dashboard
D5: =GETPIVOTDATA("[Measures].[True_Revenue]",Calcs!$A$3) -> 834310.8 | H5: =GETPIVOTDATA("[Measures].[True_Expense]",Calcs!$A$3) -> 772780.36 | L5: =GETPIVOTDATA("[Measures].[Net_Profit]",Calcs!$A$3) -> 61530.44 | P5: =GETPIVOTDATA("[Measures].[Saving Rates]",Calcs!$A$46) -> 0.19369281 | T5: =GETPIVOTDATA("[Measures].[Mapping Accuracy]",Calcs!$A$64,"[CleanedSheet].[Macro_Category]","[CleanedSheet].[Macro_Category].&[Unreconciled]") -> 0.96533595

Sheet Master2
A1: Date Received | B1: Month | C1: Account_ID | D1: Amount | E1: Transaction_Details | F1: Transaction_Type | G1: Category | H1: Type | I1: Month_Sort | J1: Fiscal_Quarter | K1: Total | L1: Flow | M1: Entity | N1: Macro_Category
A2: 45659 | B2: January | C2: 816 | D2: 17015 | E2: Sent to M_Account | F2: Expense | G2: Saving Account | H2: Debit | I2: 1 | J2: 1 | K2: -17015 | L2: Outflow | M2: M_Account | N2: Financial Account
A3: 45660 | B3: January | C3: 384 | D3: 1500 | E3: Received from CD | F3: Income | G3: Transfer | H3: Credit | I3: 1 | J3: 1 | K3: 1500 | L3: Inflow | M3: CD | N3: Payments
A4: 45661 | B4: January | C4: 3957 | D4: 181 | E4: Sent to Kimio old number | F4: Expense | G4: Phone Utilities | H4: Debit | I4: 1 | J4: 1 | K4: -181 | L4: Outflow | M4: Kimio old number | N4: Personal Expense
A5: 45662 | B5: January | C5: 6406 | D5: 1800 | E5: Received from AX | F5: Income | G5: Transfer | H5: Credit | I5: 1 | J5: 1 | K5: 1800 | L5: Inflow | M5: AX | N5: Payments
A6: 45663 | B6: January | C6: 816 | D6: 2015 | E6: Sent to M_Account | F6: Expense | G6: Saving Account | H6: Debit | I6: 1 | J6: 1 | K6: -2015 | L6: Outflow | M6: M_Account | N6: Financial Account
A7: 45664 | B7: January | C7: 559 | D7: 400 | E7: Sent to CA | F7: Expense | G7: Transfer | H7: Debit | I7: 1 | J7: 1 | K7: -400 | L7: Outflow | M7: CA | N7: Payments
A8: 45666 | B8: January | C8: 5097 | D8: 1500 | E8: Received from BI | F8: Income | G8: Transfer | H8: Credit | I8: 1 | J8: 1 | K8: 1500 | L8: Inflow | M8: BI | N8: Payments
A9: 45666 | B9: January | C9: 6807 | D9: 3000 | E9: Received from AV | F9: Income | G9: Transfer | H9: Credit | I9: 1 | J9: 1 | K9: 3000 | L9: Inflow | M9: AV | N9: Payments
A10: 45667 | B10: January | C10: 4969 | D10: 21 | E10: Sent to BuchioSmart | F10: Expense | G10: Phone Utilities | H10: Debit | I10: 1 | J10: 1 | K10: -21 | L10: Outflow | M10: BuchioSmart | N10: Personal Expense
A11: 45667 | B11: January | C11: 1082 | D11: 3500 | E11: Sent to BV | F11: Expense | G11: Transfer | H11: Debit | I11: 1 | J11: 1 | K11: -3500 | L11: Outflow | M11: BV | N11: Payments
A12: 45667 | B12: January | C12: 5572 | D12: 5173 | E12: Received from BG | F12: Income | G12: Transfer | H12: Credit | I12: 1 | J12: 1 | K12: 5173 | L12: Inflow | M12: BG | N12: Payments
A13: 45668 | B13: January | C13: 559 | D13: 400 | E13: Received from CA | F13: Income | G13: Transfer | H13: Credit | I13: 1 | J13: 1 | K13: 400 | L13: Inflow | M13: CA | N13: Payments
... A598: 46022 | B598: December | C598: 6115 | D598: 4000 | E598: Received from DD | F598: Income | G598: Transfer | H598: Credit | I598: 12 | J598: 4 | K598: 4000 | L598: Inflow | M598: DD | N598: Payments

Sheet Calcs
I2: =A23 -> Fixed Expense | J2: =A24 -> Government Payment | K2: =A25 -> Monthly Expense | L2: =A26 -> Personal Expense
A3: Row Labels | B3: Revenue | C3: Expense | D3: Net Profit | F3: Category | G3: Transfer | I3: =GETPIVOTDATA("[Measures].[Sum of Amount]",$A$22,"[CleanedSheet].[Macro_Category]","[CleanedSheet].[Macro_Category].&[Fixed Expense]") -> 185000 | J3: =GETPIVOTDATA("[Measures].[Sum of Amount]",$A$22,"[CleanedSheet].[Macro_Category]","[CleanedSheet].[Macro_Category].&[Government Payment]") -> 85598.91 | K3: =GETPIVOTDATA("[Measures].[Sum of Amount]",$A$22,"[CleanedSheet].[Macro_Category]","[CleanedSheet].[Macro_Category].&[Monthly Expense]") -> 492214.45 | L3: =GETPIVOTDATA("[Measures].[Sum of Amount]",$A$22,"[CleanedSheet].[Macro_Category]","[CleanedSheet].[Macro_Category].&[Personal Expense]") -> 9967
A4: Jan | B4: 56635 | C4: 93742.09 | D4: -37107.09 | F4: Date Received (Month) | G4: All
A5: Feb | B5: 65231 | C5: 47727.67 | D5: 17503.33
A6: Mar | B6: 78601 | C6: 70306.54 | D6: 8294.46 | F6: Row Labels | G6: True_Revenue
A7: Apr | B7: 63142 | C7: 58605.71 | D7: 4536.29 | F7: Jas | G7: 75600
A8: May | B8: 76602 | C8: 75457.96 | D8: 1144.04 | F8: CJMen | G8: 63000
A9: Jun | B9: 112292 | C9: 68281.83 | D9: 44010.17 | F9: AX | G9: 34200
A10: Jul | B10: 71581 | C10: 56672.21 | D10: 14908.79 | F10: AC | G10: 32000
A11: Aug | B11: 58312 | C11: 60561.01 | D11: -2249.01 | F11: DD | G11: 28000
A12: Sep | B12: 54362 | C12: 58051.46 | D12: -3689.46 | F12: BT | G12: 25300
A13: Oct | B13: 74732 | C13: 62669.81 | D13: 12062.19 | F13: AQ | G13: 25000
A14: Nov | B14: 78499.8 | C14: 63376.39 | D14: 15123.41 | F14: NF | G14: 23860
A15: Dec | B15: 44321 | C15: 57327.68 | D15: -13006.68 | F15: BY | G15: 19800
A16: Grand Total | B16: 834310.8 | C16: 772780.36 | D16: 61530.44 | F16: AH | G16: 19000
F17: Grand Total | G17: 345760
A20: Flow | B20: Outflow | D20: Flow | E20: Inflow
D21: Macro_Category | E21: Payments
A22: Row Labels | B22: Sum of Amount
A23: Fixed Expense | B23: 185000 | D23: Row Labels | E23: Sum of Amount
A24: Government Payment | B24: 85598.91 | D24: AJ | E24: 16500
A25: Monthly Expense | B25: 492214.45 | D25: AQ | E25: 25000
A26: Personal Expense | B26: 9967 | D26: AX | E26: 34200
A27: Grand Total | B27: 772780.36 | D27: BP | E27: 12000
D28: BY | E28: 19800
D29: CJMen | E29: 63000
A30: Row Labels | B30: Sum of Amount | D30: DD | E30: 28000
A31: Unreconciled | D31: Jas | E31: 75600
A32: Jan | B32: 700 | D32: K.UB | E32: 141000
A33: Feb | B33: 3305 | D33: NF | E33: 23860
A34: Mar | B34: 14702 | D34: Grand Total | E34: 438960
A35: Apr | B35: 8210.19
A36: May | B36: 8910
A37: Jun | B37: 10715
A38: Jul | B38: 43370
A39: Aug | B39: 6000
A40: Oct | B40: 910
A41: Nov | B41: 3760
A42: Grand Total | B42: 100582.19
A46: Row Labels | B46: Sum of Amount | C46: True_Revenue | D46: Saving Rates
...

Sheet Mapping
A1: Account ID | B1: Description | C1: MasterKey | D1: Entity (Who/What) | E1: Category | F1: Macro-Category
A2: N/a | B2: Sss | C2: Sss | D2: Sss Government | E2: Government | F2: Government Payment
A3: 9950 | B3: N/a | C3: 9950 | D3: Carmenio | E3: Transfer | F3: Payments
A4: 9807 | B4: N/a | C4: 9807 | D4: Unidentified | E4: Undisclosed | F4: Unreconciled
A5: 9619 | B5: N/a | C5: 9619 | D5: Unidentified | E5: Undisclosed | F5: Unreconciled
A6: 9438 | B6: N/a | C6: 9438 | D6: Unidentified | E6: Undisclosed | F6: Unreconciled
A7: 9162 | B7: N/a | C7: 9162 | D7: AA | E7: Transfer | F7: Payments
A8: 9090 | B8: N/a | C8: 9090 | D8: AB | E8: Transfer | F8: Payments
A9: 9032 | B9: N/a | C9: 9032 | D9: AC | E9: Transfer | F9: Payments
A10: 8758 | B10: N/a | C10: 8758 | D10: AD | E10: Transfer | F10: Payments
A11: 8652 | B11: N/a | C11: 8652 | D11: BuchioSmart | E11: Phone Utilities | F11: Personal Expense
A12: 8562 | B12: N/a | C12: 8562 | D12: Unidentified | E12: Undisclosed | F12: Unreconciled
A13: 8497 | B13: N/a | C13: 8497 | D13: AE | E13: Transfer | F13: Payments
A14: 8306 | B14: N/a | C14: 8306 | D14: Unidentified | E14: Undisclosed | F14: Unreconciled
... A47: 6119 | B47: N/a | C47: 6119 | D47: BA | E47: Transfer | F47: Payments
A48: 6115 | B48: BpiDD | C48: BpiDD | D48: DD | E48: Transfer | F48: Payments
A49: 6009 | B49: N/a | C49: 6009 | D49: BC | E49: Transfer | F49: Payments
A50: 5988 | B50: N/a | C50: 5988 | D50: Unidentified | E50: Undisclosed | F50: Unreconciled
A51: 5854 | B51: N/a | C51: 5854 | D51: JM | E51: Transfer | F51: Payments
A52: 5791 | B52: N/a | C52: 5791 | D52: Ethel | E52: Transfer | F52: Payments
A53: 5780 | B53: N/a | C53: 5780 | D53: Unidentified | E53: Undisclosed | F53: Unreconciled
A54: 5763 | B54: JasBpi | C54: 5763 | D54: Jas | E54: Transfer | F54: Payments
A55: 5715 | B55: N/a | C55: 5715 | D55: Unidentified | E55: Undisclosed | F55: Unreconciled
A56: 5680 | B56: N/a | C56: 5680 | D56: BE | E56: Transfer | F56: Payments
A57: 5672 | B57: N/a | C57: 5672 | D57: BF | E57: Transfer | F57: Payments
A58: 5572 | B58: N/a | C58: 5572 | D58: BG | E58: Transfer | F58: Payments
A59: 5340 | B59: N/a | C59: 5340 | D59: BH | E59: Transfer | F59: Payments
A60: 5125 | B60: N/a | C60: 5125 | D60: Unidentified | E60: Undisclosed | F60: Unreconciled
... A111: 0 | B111: N/a | C111: 0 | D111: CH | E111: Transfer | F111: Payments
A112: 1 | B112: Home | C112: Home | D112: Rent Home | E112: Home Expense | F112: Fixed Expense
A113: 2 | B113: Insurance | C113: Insurance | D113: Fwd | E113: Insurance Fwd | F113: Monthly Expense
A114: 3 | B114: Efund | C114: Efund | D114: Emergency | E114: Savings | F114: Monthly Savings
A115: 4 | B115: Education | C115: Education | D115: School | E115: Savings | F115: Monthly Savings
A116: 5 | B116: Plant | C116: Plant | D116: Crop | E116: Plantation | F116: Monthly Expense
A117: 6 | B117: Gloan | C117: Gloan | D117: GLoan | E117: Debt | F117: Repayment
A118: 7 | B118: Ginvest | C118: Ginvest | D118: Invest | E118: Investment | F118: Ginvestment
A119: 8 | B119: Credit card | C119: Credit card | D119: Credit Card payment | E119: Card payment | F119: Monthly Expense
A120: 9 | B120: Pagibig | C120: Pagibig | D120: Pagibig Fund | E120: Government | F120: Government Payment
A121: 10 | B121: Petty | C121: Petty | D121: Personal Cash | E121: Personal | F121: Monthly Expense
A122: 11 | B122: Loklok | C122: Loklok | D122: Tv Subscription | E122: Subscription | F122: Monthly Expense
...

Sheet  Master
A1: Date Received | B1: Month | C1: Id | D1: Category | E1: Type | F1: Amount
A2: 45659 | B2: January | C2: 816 | D2: =_xlfn.XLOOKUP(C2, Mapping!$C:$C, Mapping!$E:$E, "Check ID") -> Saving Account | E2: Debit | F2: 17015
A3: 45661 | B3: January | C3: 3957 | D3: =_xlfn.XLOOKUP(C3, Mapping!$C:$C, Mapping!$E:$E, "Check ID") -> Phone Utilities | E3: Debit | F3: 181
A4: 45663 | B4: January | C4: 816 | D4: =_xlfn.XLOOKUP(C4, Mapping!$C:$C, Mapping!$E:$E, "Check ID") -> Saving Account | E4: Debit | F4: 2015
A5: 45664 | B5: January | C5: 559 | D5: =_xlfn.XLOOKUP(C5, Mapping!$C:$C, Mapping!$E:$E, "Check ID") -> Transfer | E5: Debit | F5: 400
A6: 45667 | B6: January | C6: 4969 | D6: =_xlfn.XLOOKUP(C6, Mapping!$C:$C, Mapping!$E:$E, "Check ID") -> Phone Utilities | E6: Debit | F6: 21
A7: 45667 | B7: January | C7: 1082 | D7: =_xlfn.XLOOKUP(C7, Mapping!$C:$C, Mapping!$E:$E, "Check ID") -> Transfer | E7: Debit | F7: 3500
A8: 45669 | B8: January | C8: 5988 | D8: =_xlfn.XLOOKUP(C8, Mapping!$C:$C, Mapping!$E:$E, "Check ID") -> Undisclosed | E8: Debit | F8: 700
A9: 45672 | B9: January | C9: Pagibig | D9: =_xlfn.XLOOKUP(C9, Mapping!$C:$C, Mapping!$E:$E, "Check ID") -> Government | E9: Debit | F9: 12131.81
A10: 45673 | B10: January | C10: 1862 | D10: =_xlfn.XLOOKUP(C10, Mapping!$C:$C, Mapping!$E:$E, "Check ID") -> Transfer | E10: Debit | F10: 7000
A11: 45673 | B11: January | C11: 9032 | D11: =_xlfn.XLOOKUP(C11, Mapping!$C:$C, Mapping!$E:$E, "Check ID") -> Transfer | E11: Debit | F11: 10000
A12: 45674 | B12: January | C12: 816 | D12: =_xlfn.XLOOKUP(C12, Mapping!$C:$C, Mapping!$E:$E, "Check ID") -> Saving Account | E12: Debit | F12: 24015
A13: 45676 | B13: January | C13: 3957 | D13: =_xlfn.XLOOKUP(C13, Mapping!$C:$C, Mapping!$E:$E, "Check ID") -> Phone Utilities | E13: Debit | F13: 181
A14: 45677 | B14: January | C14: Gloan | D14: =_xlfn.XLOOKUP(C14, Mapping!$C:$C, Mapping!$E:$E, "Check ID") -> Debt | E14: Debit | F14: 2730.83
A15: 45677 | B15: January | C15: 1773 | D15: =_xlfn.XLOOKUP(C15, Mapping!$C:$C, Mapping!$E:$E, "Check ID") -> Transfer | E15: Debit | F15: 3000
A16: 45682 | B16: January | C16: 7910 | D16: =_xlfn.XLOOKUP(C16, Mapping!$C:$C, Mapping!$E:$E, "Check ID") -> Transfer | E16: Debit | F16: 1000
A17: 45687 | B17: January | C17: 9032 | D17: =_xlfn.XLOOKUP(C17, Mapping!$C:$C, Mapping!$E:$E, "Check ID") -> Transfer | E17: Debit | F17: 10000
A18: 45688 | B18: January | C18: 7261 | D18: =_xlfn.XLOOKUP(C18, Mapping!$C:$C, Mapping!$E:$E, "Check ID") -> Transfer | E18: Debit | F18: 5000
A19: 45688 | B19: January | C19: 7479 | D19: =_xlfn.XLOOKUP(C19, Mapping!$C:$C, Mapping!$E:$E, "Check ID") -> Transfer | E19: Debit | F19: 2000
A20: 45660 | B20: January | C20: 384 | D20: =_xlfn.XLOOKUP(C20, Mapping!$C:$C, Mapping!$E:$E, "Check ID") -> Transfer | E20: Credit | F20: 1500
A21: 45662 | B21: January | C21: 6406 | D21: =_xlfn.XLOOKUP(C21, Mapping!$C:$C, Mapping!$E:$E, "Check ID") -> Transfer | E21: Credit | F21: 1800
A22: 45666 | B22: January | C22: 6807 | D22: =_xlfn.XLOOKUP(C22, Mapping!$C:$C, Mapping!$E:$E, "Check ID") -> Transfer | E22: Credit | F22: 3000
A23: 45666 | B23: January | C23: 5097 | D23: =_xlfn.XLOOKUP(C23, Mapping!$C:$C, Mapping!$E:$E, "Check ID") -> Transfer | E23: Credit | F23: 1500
A24: 45667 | B24: January | C24: 5572 | D24: =_xlfn.XLOOKUP(C24, Mapping!$C:$C, Mapping!$E:$E, "Check ID") -> Transfer | E24: Credit | F24: 5173
A25: 45668 | B25: January | C25: 559 | D25: =_xlfn.XLOOKUP(C25, Mapping!$C:$C, Mapping!$E:$E, "Check ID") -> Transfer | E25: Credit | F25: 400
A26: 45670 | B26: January | C26: 5763 | D26: =_xlfn.XLOOKUP(C26, Mapping!$C:$C, Mapping!$E:$E, "Check ID") -> Transfer | E26: Credit | F26: 3600
... A36: 45675 | B36: January | C36: 7261 | D36: =_xlfn.XLOOKUP(C36, Mapping!$C:$C, Mapping!$E:$E, "Check ID") -> Transfer | E36: Credit | F36: 1200
A37: 45675 | B37: January | C37: Ginvest | D37: =_xlfn.XLOOKUP(C37, Mapping!$C:$C, Mapping!$E:$E, "Check ID") -> Investment | E37: Credit | F37: 27.01
A38: 45676 | B38: January | C38: 308 | D38: =_xlfn.XLOOKUP(C38, Mapping!$C:$C, Mapping!$E:$E, "Check ID") -> Transfer | E38: Credit | F38: 1000
A39: 45676 | B39: January | C39: 5854 | D39: =_xlfn.XLOOKUP(C39, Mapping!$C:$C, Mapping!$E:$E, "Check ID") -> Transfer | E39: Credit | F39: 1500
A40: 45676 | B40: January | C40: 8072 | D40: =_xlfn.XLOOKUP(C40, Mapping!$C:$C, Mapping!$E:$E, "Check ID") -> Transfer | E40: Credit | F40: 1500
A41: 45682 | B41: January | C41: 7133 | D41: =_xlfn.XLOOKUP(C41, Mapping!$C:$C, Mapping!$E:$E, "Check ID") -> Transfer | E41: Credit | F41: 1500
A42: 45687 | B42: January | C42: 1862 | D42: =_xlfn.XLOOKUP(C42, Mapping!$C:$C, Mapping!$E:$E, "Check ID") -> Transfer | E42: Credit | F42: 1400
A43: 45687 | B43: January | C43: 7910 | D43: =_xlfn.XLOOKUP(C43, Mapping!$C:$C, Mapping!$E:$E, "Check ID") -> Transfer | E43: Credit | F43: 1200
A44: 45687 | B44: January | C44: 9032 | D44: =_xlfn.XLOOKUP(C44, Mapping!$C:$C, Mapping!$E:$E, "Check ID") -> Transfer | E44: Credit | F44: 2000
A45: 45687 | B45: January | C45: BpiDD | D45: =_xlfn.XLOOKUP(C45, Mapping!$C:$C, Mapping!$E:$E, "Check ID") -> Transfer | E45: Credit | F45: 3000
A46: 45687 | B46: January | C46: 7276 | D46: =_xlfn.XLOOKUP(C46, Mapping!$C:$C, Mapping!$E:$E, "Check ID") -> Transfer | E46: Credit | F46: 3000
A47: 45687 | B47: January | C47: 1082 | D47: =_xlfn.XLOOKUP(C47, Mapping!$C:$C, Mapping!$E:$E, "Check ID") -> Transfer | E47: Credit | F47: 700
A48: 45687 | B48: January | C48: 9162 | D48: =_xlfn.XLOOKUP(C48, Mapping!$C:$C, Mapping!$E:$E, "Check ID") -> Transfer | E48: Credit | F48: 2000
A49: 45689 | B49: February | C49: 816 | D49: =_xlfn.XLOOKUP(C49, Mapping!$C:$C, Mapping!$E:$E, "Check ID") -> Saving Account | E49: Debit | F49: 32515
...
